# Errors
Date: 2025-10-24 12:20

## Github CI Pipeline

### Lint Code

- *Run mypy*

```
5s
Run mypy src/
src/aetherlens/config.py:25: error: Incompatible types in assignment (expression has type "str", variable has type "PostgresDsn")  [assignment]
Found 1 error in 1 file (checked 8 source files)
Error: Process completed with exit code 1.
```

### Run Tests

- *Run tests with coverage*

```
Run pytest tests/ -v --cov=src/aetherlens --cov-report=xml --cov-report=html
============================= test session starts ==============================
platform linux -- Python 3.11.13, pytest-7.4.4, pluggy-1.6.0 -- /opt/hostedtoolcache/Python/3.11.13/x64/bin/python
cachedir: .pytest_cache
rootdir: /home/runner/work/aetherlens/aetherlens
configfile: pyproject.toml
plugins: anyio-4.11.0, asyncio-0.23.8, timeout-2.4.0, cov-5.0.0, mock-3.15.1
asyncio: mode=Mode.AUTO
/opt/hostedtoolcache/Python/3.11.13/x64/lib/python3.11/site-packages/coverage/control.py:946: CoverageWarning: No data was collected. (no-data-collected); see https://coverage.readthedocs.io/en/7.11.0/messages.html#warning-no-data-collected
  self._warn("No data was collected.", slug="no-data-collected")
collecting ... collected 3 items / 2 errors

==================================== ERRORS ====================================
__________________ ERROR collecting tests/unit/test_config.py __________________
ImportError while importing test module '/home/runner/work/aetherlens/aetherlens/tests/unit/test_config.py'.
Hint: make sure your test modules/packages have valid Python names.
Traceback:
/opt/hostedtoolcache/Python/3.11.13/x64/lib/python3.11/importlib/__init__.py:126: in import_module
    return _bootstrap._gcd_import(name[level:], package, level)
tests/unit/test_config.py:3: in <module>
    from aetherlens.config import Settings
E   ModuleNotFoundError: No module named 'aetherlens'
_________________ ERROR collecting tests/unit/test_version.py __________________
ImportError while importing test module '/home/runner/work/aetherlens/aetherlens/tests/unit/test_version.py'.
Hint: make sure your test modules/packages have valid Python names.
Traceback:
/opt/hostedtoolcache/Python/3.11.13/x64/lib/python3.11/importlib/__init__.py:126: in import_module
    return _bootstrap._gcd_import(name[level:], package, level)
tests/unit/test_version.py:3: in <module>
    import aetherlens
E   ModuleNotFoundError: No module named 'aetherlens'

---------- coverage: platform linux, python 3.11.13-final-0 ----------
Name                                    Stmts   Miss   Cover   Missing
----------------------------------------------------------------------
src/aetherlens/__init__.py                  3      3   0.00%   8-10
src/aetherlens/api/__init__.py              0      0 100.00%
src/aetherlens/collection/__init__.py       0      0 100.00%
src/aetherlens/config.py                   25     25   0.00%   5-60
src/aetherlens/costs/__init__.py            0      0 100.00%
src/aetherlens/models/__init__.py           0      0 100.00%
src/aetherlens/plugins/__init__.py          0      0 100.00%
src/aetherlens/security/__init__.py         0      0 100.00%
----------------------------------------------------------------------
TOTAL                                      28     28   0.00%
Coverage HTML written to dir htmlcov
Coverage XML written to file coverage.xml

=========================== short test summary info ============================
ERROR tests/unit/test_config.py
ERROR tests/unit/test_version.py
!!!!!!!!!!!!!!!!!!! Interrupted: 2 errors during collection !!!!!!!!!!!!!!!!!!!!
============================== 2 errors in 0.16s ===============================
Error: Process completed with exit code 2.
```
